(dp1
S'output'
p2
S'<type \'exceptions.RuntimeError\'> Failure to connect, tried 5 times:\nTraceback (most recent call last):\n  File "/Users/rocky/projects/gq/web2py/gluon/packages/dal/pydal/base.py", line 446, in __init__\n    self._adapter = ADAPTERS[self._dbname](**kwargs)\n  File "/Users/rocky/projects/gq/web2py/gluon/packages/dal/pydal/adapters/base.py", line 60, in __call__\n    obj = super(AdapterMeta, cls).__call__(*args, **kwargs)\n  File "/Users/rocky/projects/gq/web2py/gluon/packages/dal/pydal/adapters/mysql.py", line 96, in __init__\n    if do_connect: self.find_driver(adapter_args,uri)\n  File "/Users/rocky/projects/gq/web2py/gluon/packages/dal/pydal/adapters/base.py", line 192, in find_driver\n    raise RuntimeError("no driver available %s" % str(self.drivers))\nRuntimeError: no driver available (\'MySQLdb\', \'pymysql\', \'mysqlconnector\')\n'
p3
sS'layer'
p4
S'/Users/rocky/projects/gq/web2py/applications/fmgqcx/models/db.py'
p5
sS'code'
p6
S"db = DAL('mysql://fmgqcp1v_root:rock4981@45.113.121.214/fmgqcp1v_gq', migrate_enabled=True)\ndb.define_table('gq',\n\tField('no', 'string', length=16),\n\tField('invest_type', 'string', length=32),\n\tField('regist_share', 'integer'),\n\tField('balance_share', 'integer'),\n\tField('dividend_share', 'integer'),\n\tField('bonus_share', 'integer'),\n\tField('user_id', 'integer', notnull=True),\n\tField('date', 'date')\n)\nfrom gluon.tools import *\nauth=Auth(db)\nauth.settings.extra_fields['auth_user']= [\n    Field('identity_card', 'string', length=18, label='\xe8\xba\xab\xe4\xbb\xbd\xe8\xaf\x81')]\nauth.define_tables(username=True)\ndb.auth_user.username.requires = IS_NOT_IN_DB(db, db.auth_user.username)\nauth.settings.login_url = URL('default', 'login')\nif not session.authorized:\n    if auth.user and not request.function == 'login':\n        session.authorized = True\n    elif not request.function == 'login':\n        redirect(URL('default', 'login'))\n"
p7
sS'snapshot'
p8
(dp9
sS'traceback'
p10
S'Traceback (most recent call last):\n  File "/Users/rocky/projects/gq/web2py/gluon/restricted.py", line 227, in restricted\n    exec ccode in environment\n  File "/Users/rocky/projects/gq/web2py/applications/fmgqcx/models/db.py", line 1, in <module>\n    db = DAL(\'mysql://fmgqcp1v_root:rock4981@45.113.121.214/fmgqcp1v_gq\', migrate_enabled=True)\n  File "/Users/rocky/projects/gq/web2py/gluon/packages/dal/pydal/base.py", line 174, in __call__\n    obj = super(MetaDAL, cls).__call__(*args, **kwargs)\n  File "/Users/rocky/projects/gq/web2py/gluon/packages/dal/pydal/base.py", line 473, in __init__\n    "Failure to connect, tried %d times:\\n%s" % (attempts, tb)\nRuntimeError: Failure to connect, tried 5 times:\nTraceback (most recent call last):\n  File "/Users/rocky/projects/gq/web2py/gluon/packages/dal/pydal/base.py", line 446, in __init__\n    self._adapter = ADAPTERS[self._dbname](**kwargs)\n  File "/Users/rocky/projects/gq/web2py/gluon/packages/dal/pydal/adapters/base.py", line 60, in __call__\n    obj = super(AdapterMeta, cls).__call__(*args, **kwargs)\n  File "/Users/rocky/projects/gq/web2py/gluon/packages/dal/pydal/adapters/mysql.py", line 96, in __init__\n    if do_connect: self.find_driver(adapter_args,uri)\n  File "/Users/rocky/projects/gq/web2py/gluon/packages/dal/pydal/adapters/base.py", line 192, in find_driver\n    raise RuntimeError("no driver available %s" % str(self.drivers))\nRuntimeError: no driver available (\'MySQLdb\', \'pymysql\', \'mysqlconnector\')\n\n'
p11
s.